Workbook

Sheet Data
A1: Loan ID | B1: Customer | C1: Gender | D1: Age | E1: County | F1: Loan Type | G1: Loan Amount | H1: Interest Rate | I1: Term (Months) | J1: Monthly Income | K1: Credit Score | L1: Amount Paid | M1: Outstanding | N1: Status | O1: Application Date
A2: L001 | B2: John Mwangi | C2: M | D2: 34 | E2: Nairobi | F2: Asset Finance | G2: 850000 | H2: 0.14 | I2: 36 | J2: 85000 | K2: 720 | L2: 425000 | M2: 425000 | N2: Performing | O2: 46027
A3: L002 | B3: Mary Wanjiku | C3: F | D3: 29 | E3: Kiambu | F3: Logbook | G3: 350000 | H3: 0.18 | I3: 24 | J3: 65000 | K3: 680 | L3: 175000 | M3: 175000 | N3: Performing | O3: 46030
A4: L003 | B4: Peter Otieno | C4: M | D4: 42 | E4: Kisumu | F4: Asset Finance | G4: 1200000 | H4: 0.15 | I4: 48 | J4: 120000 | K4: 710 | L4: 300000 | M4: 900000 | N4: Performing | O4: 46032
A5: L004 | B5: Jane Akinyi | C5: F | D5: 37 | E5: Nairobi | F5: Boda Loan | G5: 180000 | H5: 0.2 | I5: 18 | J5: 42000 | K5: 610 | L5: 60000 | M5: 120000 | N5: Arrears | O5: 46034
A6: L005 | B6: David Kamau | C6: M | D6: 31 | E6: Nakuru | F6: Logbook | G6: 500000 | H6: 0.17 | I6: 30 | J6: 75000 | K6: 695 | L6: 250000 | M6: 250000 | N6: Performing | O6: 46037
A7: L006 | B7: Grace Njeri | C7: F | D7: 45 | E7: Kiambu | F7: Asset Finance | G7: 1500000 | H7: 0.14 | I7: 48 | J7: 150000 | K7: 735 | L7: 375000 | M7: 1125000 | N7: Performing | O7: 46040
A8: L007 | B8: Samuel Ochieng | C8: M | D8: 28 | E8: Kisumu | F8: Boda Loan | G8: 150000 | H8: 0.21 | I8: 18 | J8: 50000 | K8: 590 | L8: 50000 | M8: 100000 | N8: Arrears | O8: 46042
A9: L008 | B9: Lucy Wambui | C9: F | D9: 33 | E9: Nairobi | F9: Logbook | G9: 420000 | H9: 0.18 | I9: 24 | J9: 70000 | K9: 665 | L9: 315000 | M9: 105000 | N9: Performing | O9: 46044
A10: L009 | B10: Brian Kiptoo | C10: M | D10: 39 | E10: Uasin Gishu | F10: Asset Finance | G10: 950000 | H10: 0.15 | I10: 36 | J10: 90000 | K10: 705 | L10: 475000 | M10: 475000 | N10: Performing | O10: 46047
A11: L010 | B11: Ann Chebet | C11: F | D11: 26 | E11: Nakuru | F11: Boda Loan | G11: 200000 | H11: 0.22 | I11: 18 | J11: 45000 | K11: 575 | L11: 40000 | M11: 160000 | N11: Default | O11: 46050
A12: L011 | B12: Kevin Mutua | C12: M | D12: 36 | E12: Machakos | F12: Logbook | G12: 600000 | H12: 0.17 | I12: 30 | J12: 80000 | K12: 690 | L12: 300000 | M12: 300000 | N12: Performing | O12: 46055
A13: L012 | B13: Sarah Atieno | C13: F | D13: 41 | E13: Kisumu | F13: Asset Finance | G13: 1100000 | H13: 0.15 | I13: 48 | J13: 115000 | K13: 725 | L13: 275000 | M13: 825000 | N13: Performing | O13: 46058
... A21: L020 | B21: Faith Auma | C21: F | D21: 43 | E21: Nairobi | F21: Asset Finance | G21: 1250000 | H21: 0.15 | I21: 48 | J21: 130000 | K21: 715 | L21: 312500 | M21: 937500 | N21: Performing | O21: 46081

Sheet Processing
A2: Loan ID | B2: Customer | C2: Payment-to-Income Ratio | D2: Monthly Payment | E2: Total Repayment | F2: Interest Earned | G2: Age Group | H2: Risk Score Category | I2: Payment Status Score | K2: Narations
A3: L001 | B3: John Mwangi | C3: =ROUND(ABS(Data!J2/Processing!D3),2) -> 2.93 | D3: =ABS(PMT(Data!H2/12,Data!I2,Data!G2)) -> 29050.985 | E3: =PRODUCT(D3,Data!I2) -> 1045835.5 | F3: =E3-Data!G2 -> 195835.47 | G3: {=_xlfn.IFS(Data!D2<30,"Young",Data!D2<40,"Mid",Data!D2>40,"Senior")} -> Mid | H3: {=_xlfn.IFS(Data!K2>=700,"Low",Data!K2>=650,"Medium",Data!K2<=650,"High")} -> Low | I3: {=_xlfn.IFS(Data!N2="Performing",1,Data!N2="Arrears",2,Data!N2="Default",3)} -> 1
A4: L002 | B4: Mary Wanjiku | C4: =ROUND(ABS(Data!J3/Processing!D4),2) -> 3.72 | D4: =ABS(PMT(Data!H3/12,Data!I3,Data!G3)) -> 17473.436 | E4: =PRODUCT(D4,Data!I3) -> 419362.46 | F4: =E4-Data!G3 -> 69362.457 | G4: {=_xlfn.IFS(Data!D3<30,"Young",Data!D3<40,"Mid",Data!D3>40,"Senior")} -> Young | H4: {=_xlfn.IFS(Data!K3>=700,"Low",Data!K3>=650,"Medium",Data!K3<=650,"High")} -> Medium | I4: {=_xlfn.IFS(Data!N3="Performing",1,Data!N3="Arrears",2,Data!N3="Default",3)} -> 1
A5: L003 | B5: Peter Otieno | C5: =ROUND(ABS(Data!J4/Processing!D5),2) -> 3.59 | D5: =ABS(PMT(Data!H4/12,Data!I4,Data!G4)) -> 33396.898 | E5: =PRODUCT(D5,Data!I4) -> 1603051.1 | F5: =E5-Data!G4 -> 403051.1 | G5: {=_xlfn.IFS(Data!D4<30,"Young",Data!D4<40,"Mid",Data!D4>40,"Senior")} -> Senior | H5: {=_xlfn.IFS(Data!K4>=700,"Low",Data!K4>=650,"Medium",Data!K4<=650,"High")} -> Low | I5: {=_xlfn.IFS(Data!N4="Performing",1,Data!N4="Arrears",2,Data!N4="Default",3)} -> 1
A6: L004 | B6: Jane Akinyi | C6: =ROUND(ABS(Data!J5/Processing!D6),2) -> 3.6 | D6: =ABS(PMT(Data!H5/12,Data!I5,Data!G5)) -> 11657.376 | E6: =PRODUCT(D6,Data!I5) -> 209832.77 | F6: =E6-Data!G5 -> 29832.77 | G6: {=_xlfn.IFS(Data!D5<30,"Young",Data!D5<40,"Mid",Data!D5>40,"Senior")} -> Mid | H6: {=_xlfn.IFS(Data!K5>=700,"Low",Data!K5>=650,"Medium",Data!K5<=650,"High")} -> High | I6: {=_xlfn.IFS(Data!N5="Performing",1,Data!N5="Arrears",2,Data!N5="Default",3)} -> 2
A7: L005 | B7: David Kamau | C7: =ROUND(ABS(Data!J6/Processing!D7),2) -> 3.65 | D7: =ABS(PMT(Data!H6/12,Data!I6,Data!G6)) -> 20574.483 | E7: =PRODUCT(D7,Data!I6) -> 617234.5 | F7: =E7-Data!G6 -> 117234.5 | G7: {=_xlfn.IFS(Data!D6<30,"Young",Data!D6<40,"Mid",Data!D6>40,"Senior")} -> Mid | H7: {=_xlfn.IFS(Data!K6>=700,"Low",Data!K6>=650,"Medium",Data!K6<=650,"High")} -> Medium | I7: {=_xlfn.IFS(Data!N6="Performing",1,Data!N6="Arrears",2,Data!N6="Default",3)} -> 1
A8: L006 | B8: Grace Njeri | C8: =ROUND(ABS(Data!J7/Processing!D8),2) -> 3.66 | D8: =ABS(PMT(Data!H7/12,Data!I7,Data!G7)) -> 40989.715 | E8: =PRODUCT(D8,Data!I7) -> 1967506.3 | F8: =E8-Data!G7 -> 467506.31 | G8: {=_xlfn.IFS(Data!D7<30,"Young",Data!D7<40,"Mid",Data!D7>40,"Senior")} -> Senior | H8: {=_xlfn.IFS(Data!K7>=700,"Low",Data!K7>=650,"Medium",Data!K7<=650,"High")} -> Low | I8: {=_xlfn.IFS(Data!N7="Performing",1,Data!N7="Arrears",2,Data!N7="Default",3)} -> 1
A9: L007 | B9: Samuel Ochieng | C9: =ROUND(ABS(Data!J8/Processing!D9),2) -> 5.11 | D9: =ABS(PMT(Data!H8/12,Data!I8,Data!G8)) -> 9786.7387 | E9: =PRODUCT(D9,Data!I8) -> 176161.3 | F9: =E9-Data!G8 -> 26161.296 | G9: {=_xlfn.IFS(Data!D8<30,"Young",Data!D8<40,"Mid",Data!D8>40,"Senior")} -> Young | H9: {=_xlfn.IFS(Data!K8>=700,"Low",Data!K8>=650,"Medium",Data!K8<=650,"High")} -> High | I9: {=_xlfn.IFS(Data!N8="Performing",1,Data!N8="Arrears",2,Data!N8="Default",3)} -> 2
A10: L008 | B10: Lucy Wambui | C10: =ROUND(ABS(Data!J9/Processing!D10),2) -> 3.34 | D10: =ABS(PMT(Data!H9/12,Data!I9,Data!G9)) -> 20968.123 | E10: =PRODUCT(D10,Data!I9) -> 503234.95 | F10: =E10-Data!G9 -> 83234.948 | G10: {=_xlfn.IFS(Data!D9<30,"Young",Data!D9<40,"Mid",Data!D9>40,"Senior")} -> Mid | H10: {=_xlfn.IFS(Data!K9>=700,"Low",Data!K9>=650,"Medium",Data!K9<=650,"High")} -> Medium | I10: {=_xlfn.IFS(Data!N9="Performing",1,Data!N9="Arrears",2,Data!N9="Default",3)} -> 1
A11: L009 | B11: Brian Kiptoo | C11: =ROUND(ABS(Data!J10/Processing!D11),2) -> 2.73 | D11: =ABS(PMT(Data!H10/12,Data!I10,Data!G10)) -> 32932.062 | E11: =PRODUCT(D11,Data!I10) -> 1185554.2 | F11: =E11-Data!G10 -> 235554.23 | G11: {=_xlfn.IFS(Data!D10<30,"Young",Data!D10<40,"Mid",Data!D10>40,"Senior")} -> Mid | H11: {=_xlfn.IFS(Data!K10>=700,"Low",Data!K10>=650,"Medium",Data!K10<=650,"High")} -> Low | I11: {=_xlfn.IFS(Data!N10="Performing",1,Data!N10="Arrears",2,Data!N10="Default",3)} -> 1
A12: L010 | B12: Ann Chebet | C12: =ROUND(ABS(Data!J11/Processing!D12),2) -> 3.42 | D12: =ABS(PMT(Data!H11/12,Data!I11,Data!G11)) -> 13145.73 | E12: =PRODUCT(D12,Data!I11) -> 236623.15 | F12: =E12-Data!G11 -> 36623.148 | G12: {=_xlfn.IFS(Data!D11<30,"Young",Data!D11<40,"Mid",Data!D11>40,"Senior")} -> Young | H12: {=_xlfn.IFS(Data!K11>=700,"Low",Data!K11>=650,"Medium",Data!K11<=650,"High")} -> High | I12: {=_xlfn.IFS(Data!N11="Performing",1,Data!N11="Arrears",2,Data!N11="Default",3)} -> 3
A13: L011 | B13: Kevin Mutua | C13: =ROUND(ABS(Data!J12/Processing!D13),2) -> 3.24 | D13: =ABS(PMT(Data!H12/12,Data!I12,Data!G12)) -> 24689.38 | E13: =PRODUCT(D13,Data!I12) -> 740681.41 | F13: =E13-Data!G12 -> 140681.41 | G13: {=_xlfn.IFS(Data!D12<30,"Young",Data!D12<40,"Mid",Data!D12>40,"Senior")} -> Mid | H13: {=_xlfn.IFS(Data!K12>=700,"Low",Data!K12>=650,"Medium",Data!K12<=650,"High")} -> Medium | I13: {=_xlfn.IFS(Data!N12="Performing",1,Data!N12="Arrears",2,Data!N12="Default",3)} -> 1
A14: L012 | B14: Sarah Atieno | C14: =ROUND(ABS(Data!J13/Processing!D14),2) -> 3.76 | D14: =ABS(PMT(Data!H13/12,Data!I13,Data!G13)) -> 30613.823 | E14: =PRODUCT(D14,Data!I13) -> 1469463.5 | F14: =E14-Data!G13 -> 369463.51 | G14: {=_xlfn.IFS(Data!D13<30,"Young",Data!D13<40,"Mid",Data!D13>40,"Senior")} -> Senior | H14: {=_xlfn.IFS(Data!K13>=700,"Low",Data!K13>=650,"Medium",Data!K13<=650,"High")} -> Low | I14: {=_xlfn.IFS(Data!N13="Performing",1,Data!N13="Arrears",2,Data!N13="Default",3)} -> 1
... A22: L020 | B22: Faith Auma | C22: =ROUND(ABS(Data!J21/Processing!D22),2) -> 3.74 | D22: =ABS(PMT(Data!H21/12,Data!I21,Data!G21)) -> 34788.435 | E22: =PRODUCT(D22,Data!I21) -> 1669844.9 | F22: =E22-Data!G21 -> 419844.9 | G22: {=_xlfn.IFS(Data!D21<30,"Young",Data!D21<40,"Mid",Data!D21>40,"Senior")} -> Senior | H22: {=_xlfn.IFS(Data!K21>=700,"Low",Data!K21>=650,"Medium",Data!K21<=650,"High")} -> Low | I22: {=_xlfn.IFS(Data!N21="Performing",1,Data!N21="Arrears",2,Data!N21="Default",3)} -> 1

Sheet Merged
A1: Loan ID | B1: Customer | C1: Gender | D1: Age | E1: County | F1: Loan Type | G1: Loan Amount | H1: Interest Rate | I1: Term (Months) | J1: Monthly Income | K1: Credit Score | L1: Amount Paid | M1: Outstanding | N1: Status | O1: Application Date | P1: Payment-to-Income Ratio | Q1: Monthly Payment | R1: Total Repayment | S1: Interest Earned | T1: Age Group | U1: Risk Score Category | V1: Payment Status Score
A2: L001 | B2: John Mwangi | C2: M | D2: 34 | E2: Nairobi | F2: Asset Finance | G2: 850000 | H2: 0.14 | I2: 36 | J2: 85000 | K2: 720 | L2: 425000 | M2: 425000 | N2: Performing | O2: 46027 | P2: 2.93 | Q2: 29050.985 | R2: 1045835.5 | S2: 195835.47 | T2: Mid | U2: Low | V2: 1
A3: L002 | B3: Mary Wanjiku | C3: F | D3: 29 | E3: Kiambu | F3: Logbook | G3: 350000 | H3: 0.18 | I3: 24 | J3: 65000 | K3: 680 | L3: 175000 | M3: 175000 | N3: Performing | O3: 46030 | P3: 3.72 | Q3: 17473.436 | R3: 419362.46 | S3: 69362.457 | T3: Young | U3: Medium | V3: 1
A4: L003 | B4: Peter Otieno | C4: M | D4: 42 | E4: Kisumu | F4: Asset Finance | G4: 1200000 | H4: 0.15 | I4: 48 | J4: 120000 | K4: 710 | L4: 300000 | M4: 900000 | N4: Performing | O4: 46032 | P4: 3.59 | Q4: 33396.898 | R4: 1603051.1 | S4: 403051.1 | T4: Senior | U4: Low | V4: 1
A5: L004 | B5: Jane Akinyi | C5: F | D5: 37 | E5: Nairobi | F5: Boda Loan | G5: 180000 | H5: 0.2 | I5: 18 | J5: 42000 | K5: 610 | L5: 60000 | M5: 120000 | N5: Arrears | O5: 46034 | P5: 3.6 | Q5: 11657.376 | R5: 209832.77 | S5: 29832.77 | T5: Mid | U5: High | V5: 2
A6: L005 | B6: David Kamau | C6: M | D6: 31 | E6: Nakuru | F6: Logbook | G6: 500000 | H6: 0.17 | I6: 30 | J6: 75000 | K6: 695 | L6: 250000 | M6: 250000 | N6: Performing | O6: 46037 | P6: 3.65 | Q6: 20574.483 | R6: 617234.5 | S6: 117234.5 | T6: Mid | U6: Medium | V6: 1
A7: L006 | B7: Grace Njeri | C7: F | D7: 45 | E7: Kiambu | F7: Asset Finance | G7: 1500000 | H7: 0.14 | I7: 48 | J7: 150000 | K7: 735 | L7: 375000 | M7: 1125000 | N7: Performing | O7: 46040 | P7: 3.66 | Q7: 40989.715 | R7: 1967506.3 | S7: 467506.31 | T7: Senior | U7: Low | V7: 1
A8: L007 | B8: Samuel Ochieng | C8: M | D8: 28 | E8: Kisumu | F8: Boda Loan | G8: 150000 | H8: 0.21 | I8: 18 | J8: 50000 | K8: 590 | L8: 50000 | M8: 100000 | N8: Arrears | O8: 46042 | P8: 5.11 | Q8: 9786.7387 | R8: 176161.3 | S8: 26161.296 | T8: Young | U8: High | V8: 2
A9: L008 | B9: Lucy Wambui | C9: F | D9: 33 | E9: Nairobi | F9: Logbook | G9: 420000 | H9: 0.18 | I9: 24 | J9: 70000 | K9: 665 | L9: 315000 | M9: 105000 | N9: Performing | O9: 46044 | P9: 3.34 | Q9: 20968.123 | R9: 503234.95 | S9: 83234.948 | T9: Mid | U9: Medium | V9: 1
A10: L009 | B10: Brian Kiptoo | C10: M | D10: 39 | E10: Uasin Gishu | F10: Asset Finance | G10: 950000 | H10: 0.15 | I10: 36 | J10: 90000 | K10: 705 | L10: 475000 | M10: 475000 | N10: Performing | O10: 46047 | P10: 2.73 | Q10: 32932.062 | R10: 1185554.2 | S10: 235554.23 | T10: Mid | U10: Low | V10: 1
A11: L010 | B11: Ann Chebet | C11: F | D11: 26 | E11: Nakuru | F11: Boda Loan | G11: 200000 | H11: 0.22 | I11: 18 | J11: 45000 | K11: 575 | L11: 40000 | M11: 160000 | N11: Default | O11: 46050 | P11: 3.42 | Q11: 13145.73 | R11: 236623.15 | S11: 36623.148 | T11: Young | U11: High | V11: 3
A12: L011 | B12: Kevin Mutua | C12: M | D12: 36 | E12: Machakos | F12: Logbook | G12: 600000 | H12: 0.17 | I12: 30 | J12: 80000 | K12: 690 | L12: 300000 | M12: 300000 | N12: Performing | O12: 46055 | P12: 3.24 | Q12: 24689.38 | R12: 740681.41 | S12: 140681.41 | T12: Mid | U12: Medium | V12: 1
A13: L012 | B13: Sarah Atieno | C13: F | D13: 41 | E13: Kisumu | F13: Asset Finance | G13: 1100000 | H13: 0.15 | I13: 48 | J13: 115000 | K13: 725 | L13: 275000 | M13: 825000 | N13: Performing | O13: 46058 | P13: 3.76 | Q13: 30613.823 | R13: 1469463.5 | S13: 369463.51 | T13: Senior | U13: Low | V13: 1
... A21: L020 | B21: Faith Auma | C21: F | D21: 43 | E21: Nairobi | F21: Asset Finance | G21: 1250000 | H21: 0.15 | I21: 48 | J21: 130000 | K21: 715 | L21: 312500 | M21: 937500 | N21: Performing | O21: 46081 | P21: 3.74 | Q21: 34788.435 | R21: 1669844.9 | S21: 419844.9 | T21: Senior | U21: Low | V21: 1

Sheet Analysis
B2: 1. Risk Segmentation Analysis
B3: Column Labels
B4: Count of Loan ID | E4: Sum of Loan Amount | H4: Sum of Outstanding | K4: Total Count of Loan ID | L4: Total Sum of Loan Amount | M4: Total Sum of Outstanding
A5: Risk | B5: Arrears | C5: Default | D5: Performing | E5: Arrears | F5: Default | G5: Performing | H5: Arrears | I5: Default | J5: Performing
A6: High | B6: 3 | C6: 1 | D6: 1 | E6: 505000 | F6: 200000 | G6: 160000 | H6: 307500 | I6: 160000 | J6: 80000 | K6: 5 | L6: 865000 | M6: 547500
A7: Low | D7: 8 | G7: 8750000 | J7: 5975000 | K7: 8 | L7: 8750000 | M7: 5975000
A8: Medium | B8: 1 | D8: 6 | E8: 1000000 | G8: 2700000 | H8: 750000 | J8: 1245000 | K8: 7 | L8: 3700000 | M8: 1995000
A9: Grand Total | B9: 4 | C9: 1 | D9: 15 | E9: 1505000 | F9: 200000 | G9: 11610000 | H9: 1057500 | I9: 160000 | J9: 7300000 | K9: 20 | L9: 13315000 | M9: 8517500
A11: Expected Insight: | C11: High-risk customers may have higher default rates, suggesting a need to tighten lending criteria.
B13: 2.Geographic Performance Analysis
B14: Column Labels
B15: Arrears | E15: Default | H15: Performing | K15: Total Sum of Outstanding | L15: Total Count of Loan ID | M15: Total Sum of Loan Amount
A16: County | B16: Sum of Outstanding | C16: Count of Loan ID | D16: Sum of Loan Amount | E16: Sum of Outstanding | F16: Count of Loan ID | G16: Sum of Loan Amount | H16: Sum of Outstanding | I16: Count of Loan ID | J16: Sum of Loan Amount
A17: Kiambu | H17: 1800000 | I17: 4 | J17: 2850000 | K17: 1800000 | L17: 4 | M17: 2850000
A18: Kisumu | B18: 850000 | C18: 2 | D18: 1150000 | H18: 1725000 | I18: 2 | J18: 2300000 | K18: 2575000 | L18: 4 | M18: 3450000
A19: Machakos | H19: 300000 | I19: 1 | J19: 600000 | K19: 300000 | L19: 1 | M19: 600000
A20: Nairobi | B20: 207500 | C20: 2 | D20: 355000 | H20: 1657500 | I20: 4 | J20: 2900000 | K20: 1865000 | L20: 6 | M20: 3255000
A21: Nakuru | E21: 160000 | F21: 1 | G21: 200000 | H21: 330000 | I21: 2 | J21: 660000 | K21: 490000 | L21: 3 | M21: 860000
A22: Uasin Gishu | H22: 1487500 | I22: 2 | J22: 2300000 | K22: 1487500 | L22: 2 | M22: 2300000
A23: Grand Total | B23: 1057500 | C23: 4 | D23: 1505000 | E23: 160000 | F23: 1 | G23: 200000 | H23: 7300000 | I23: 15 | J23: 11610000 | K23: 8517500 | L23: 20 | M23: 13315000
A25: Expected Insight: | C25: Some counties may show higher delinquency rates—targeting collection efforts or adjusting lending policies there.
B27: 3.Product Performance Analysis
B28: Column Labels
B29: Sum of Outstanding | E29: Sum of Loan Amount | H29: Average of Interest Rate | K29: Total Sum of Outstanding | L29: Total Sum of Loan Amount | M29: Total Average of Interest Rate
A30: County | B30: Arrears | C30: Default | D30: Performing | E30: Arrears | F30: Default | G30: Performing | H30: Arrears | I30: Default | J30: Performing
A31: Asset Finance | B31: 750000 | D31: 5700000 | E31: 1000000 | G31: 8200000 | H31: 0.16 | J31: 0.14571429 | K31: 6450000 | L31: 9200000 | M31: 0.1475
A32: Boda Loan | B32: 307500 | C32: 160000 | D32: 80000 | E32: 505000 | F32: 200000 | G32: 160000 | H32: 0.20333333 | I32: 0.22 | J32: 0.21 | K32: 547500 | L32: 865000 | M32: 0.208
A33: Logbook | D33: 1520000 | G33: 3250000 | J33: 0.17714286 | K33: 1520000 | L33: 3250000 | M33: 0.17714286
A34: Grand Total | B34: 1057500 | C34: 160000 | D34: 7300000 | E34: 1505000 | F34: 200000 | G34: 11610000 | H34: 0.1925 | I34: 0.22 | J34: 0.16466667 | K34: 8517500 | L34: 13315000 | M34: 0.173
A36: Expected Insight: | C36: Boda Loans show higher interest rates but also higher risk—trade-off analysis.
B38: 4.Customer Demographics Analysis
B39: Column Labels
B40: Sum of Outstanding | E40: Sum of Loan Amount | H40: Sum of Credit Score | K40: Total Sum of Outstanding | L40: Total Sum of Loan Amount | M40: Total Sum of Credit Score
A41: Group Age | B41: Arrears | C41: Default | D41: Performing | E41: Arrears | F41: Default | G41: Performing | H41: Arrears | I41: Default | J41: Performing
A42: Mid | B42: 0.19621749 | C42: 0 | D42: 0.30753425 | E42: 355000 | G42: 4700000 | H42: 1210 | J42: 5500 | K42: 0.2879366 | L42: 5055000 | M42: 6710
A43: High | B43: 0.19621749 | C43: 0 | D43: 0 | E43: 355000 | H43: 1210 | K43: 0.024361608 | L43: 355000 | M43: 1210
A44: F | B44: 0.11347518 | C44: 0 | D44: 0 | E44: 180000 | H44: 610 | K44: 0.014088641 | L44: 180000 | M44: 610
A45: M | B45: 0.082742317 | C45: 0 | D45: 0 | E45: 175000 | H45: 600 | K45: 0.010272967 | L45: 175000 | M45: 600
A46: Low | B46: 0 | C46: 0 | D46: 0.1609589 | G46: 2350000 | J46: 2125 | K46: 0.13795128 | L46: 2350000 | M46: 2125
A47: M | B47: 0 | C47: 0 | D47: 0.1609589 | G47: 2350000 | J47: 2125 | K47: 0.13795128 | L47: 2350000 | M47: 2125
...

Sheet Portfolio Summary
A2: Portifolio Summary
A3: Metric | B3: How to Calculate | C3: Values
A4: Total Portfolio Value | B4: SUM(Loan Amount) → $ 12.5M | C4: =SUM(Data!G2:G21) -> 13315000
A5: Average Loan Size | B5: AVERAGE(Loan Amount) → $ 665,750 | C5: =AVERAGE(Data!G2:G21) -> 665750
A6: Performing Rate | B6: COUNTIF(Status,"Performing")/COUNTA(Status) → 75% | C6: =COUNTIF(Processing!I3:I22,1)/COUNTA(Processing!I3:I22) -> 0.75
A7: PAR (Portfolio at Risk) | B7: Loans in arrears/default / Total portfolio → 20% | C7: =(COUNTIF(Processing!I3:I22,2)/COUNTIF(Processing!I3:I22,3))/COUNT(Processing!I3:I22) -> 0.2
A8: Average Interest Rate | B8: AVERAGE(Interest Rate) → 17.1% | C8: =AVERAGE(Data!H2:H21) -> 0.173
A9: Total Interest Earned | B9: SUM(Interest Earned) →$ 3.6M | C9: =SUM(Processing!F3:F22) -> 3635569.2
