Workbook

Sheet SAVING
E2: Monthly Savings/Contributions
E3: JAN | F3: FEB | G3: MAR | H3: APR | I3: MAY | J3: JUN | K3: JUL | L3: AUG | M3: SEP | N3: OCT | O3: NOV | P3: DEC
D4: Eric
D5: Ethel
D6: Mary
D7: Isaac | E7: 20000 | F7: 10000 | G7: 13000 | H7: 20000 | I7: 7000 | J7: 8000 | K7: 7000 | L7: 2000 | M7: 2000
D8: Ruth
D9: Eric.N
D10: Daniel
D11: Casmir
D12: Phanice
D13: Duncan
D14: Allan
D15: Colince
D16: Florence
D17: Ann
E20: Monthly running/cummulative savings
E21: JAN | F21: FEB | G21: MAR | H21: APR | I21: MAY | J21: JUN | K21: JUL | L21: AUG | M21: SEP | N21: OCT | O21: NOV | P21: DEC
D22: Eric | E22: =E4 -> 0 | F22: =SUM(E22,F4) -> 0 | G22: =SUM(F22,G4) -> 0 | H22: =SUM(G22,H4) -> 0 | I22: =SUM(H22,I4) -> 0 | J22: =SUM(I22,J4) -> 0 | K22: =SUM(J22,K4) -> 0 | L22: =SUM(K22,L4) -> 0 | M22: =SUM(L22,M4) -> 0 | ... P22: =SUM(O22,P4) -> 0
D23: Ethel | E23: =E5 -> 0 | F23: =SUM(E23,F5) -> 0 | G23: =SUM(F23,G5) -> 0 | H23: =SUM(G23,H5) -> 0 | I23: =SUM(H23,I5) -> 0 | J23: =SUM(I23,J5) -> 0 | K23: =SUM(J23,K5) -> 0 | L23: =SUM(K23,L5) -> 0 | M23: =SUM(L23,M5) -> 0 | ... P23: =SUM(O23,P5) -> 0
D24: Mary | E24: =E6 -> 0 | F24: =SUM(E24,F6) -> 0 | G24: =SUM(F24,G6) -> 0 | H24: =SUM(G24,H6) -> 0 | I24: =SUM(H24,I6) -> 0 | J24: =SUM(I24,J6) -> 0 | K24: =SUM(J24,K6) -> 0 | L24: =SUM(K24,L6) -> 0 | M24: =SUM(L24,M6) -> 0 | ... P24: =SUM(O24,P6) -> 0
D25: Isaac | E25: =E7 -> 20000 | F25: =SUM(E25,F7) -> 30000 | G25: =SUM(F25,G7) -> 43000 | H25: =SUM(G25,H7) -> 63000 | I25: =SUM(H25,I7) -> 70000 | J25: =SUM(I25,J7) -> 78000 | K25: =SUM(J25,K7) -> 85000 | L25: =SUM(K25,L7) -> 87000 | M25: =SUM(L25,M7) -> 89000 | ... P25: =SUM(O25,P7) -> 89000
D26: Ruth | E26: =E8 -> 0 | F26: =SUM(E26,F8) -> 0 | G26: =SUM(F26,G8) -> 0 | H26: =SUM(G26,H8) -> 0 | I26: =SUM(H26,I8) -> 0 | J26: =SUM(I26,J8) -> 0 | K26: =SUM(J26,K8) -> 0 | L26: =SUM(K26,L8) -> 0 | M26: =SUM(L26,M8) -> 0 | ... P26: =SUM(O26,P8) -> 0
D27: Eric.N | E27: =E9 -> 0 | F27: =SUM(E27,F9) -> 0 | G27: =SUM(F27,G9) -> 0 | H27: =SUM(G27,H9) -> 0 | I27: =SUM(H27,I9) -> 0 | J27: =SUM(I27,J9) -> 0 | K27: =SUM(J27,K9) -> 0 | L27: =SUM(K27,L9) -> 0 | M27: =SUM(L27,M9) -> 0 | ... P27: =SUM(O27,P9) -> 0
D28: Daniel | E28: =E10 -> 0 | F28: =SUM(E28,F10) -> 0 | G28: =SUM(F28,G10) -> 0 | H28: =SUM(G28,H10) -> 0 | I28: =SUM(H28,I10) -> 0 | J28: =SUM(I28,J10) -> 0 | K28: =SUM(J28,K10) -> 0 | L28: =SUM(K28,L10) -> 0 | M28: =SUM(L28,M10) -> 0 | ... P28: =SUM(O28,P10) -> 0
D29: Casmir | E29: =E11 -> 0 | F29: =SUM(E29,F11) -> 0 | G29: =SUM(F29,G11) -> 0 | H29: =SUM(G29,H11) -> 0 | I29: =SUM(H29,I11) -> 0 | J29: =SUM(I29,J11) -> 0 | K29: =SUM(J29,K11) -> 0 | L29: =SUM(K29,L11) -> 0 | M29: =SUM(L29,M11) -> 0 | ... P29: =SUM(O29,P11) -> 0
D30: Phanice | E30: =E12 -> 0 | F30: =SUM(E30,F12) -> 0 | G30: =SUM(F30,G12) -> 0 | H30: =SUM(G30,H12) -> 0 | I30: =SUM(H30,I12) -> 0 | J30: =SUM(I30,J12) -> 0 | K30: =SUM(J30,K12) -> 0 | L30: =SUM(K30,L12) -> 0 | M30: =SUM(L30,M12) -> 0 | ... P30: =SUM(O30,P12) -> 0
D31: Duncan | E31: =E13 -> 0 | F31: =SUM(E31,F13) -> 0 | G31: =SUM(F31,G13) -> 0 | H31: =SUM(G31,H13) -> 0 | I31: =SUM(H31,I13) -> 0 | J31: =SUM(I31,J13) -> 0 | K31: =SUM(J31,K13) -> 0 | L31: =SUM(K31,L13) -> 0 | M31: =SUM(L31,M13) -> 0 | ... P31: =SUM(O31,P13) -> 0
D32: Allan | E32: =E14 -> 0 | F32: =SUM(E32,F14) -> 0 | G32: =SUM(F32,G14) -> 0 | H32: =SUM(G32,H14) -> 0 | I32: =SUM(H32,I14) -> 0 | J32: =SUM(I32,J14) -> 0 | K32: =SUM(J32,K14) -> 0 | L32: =SUM(K32,L14) -> 0 | M32: =SUM(L32,M14) -> 0 | ... P32: =SUM(O32,P14) -> 0
D33: Colince | E33: =E15 -> 0 | F33: =SUM(E33,F15) -> 0 | G33: =SUM(F33,G15) -> 0 | H33: =SUM(G33,H15) -> 0 | I33: =SUM(H33,I15) -> 0 | J33: =SUM(I33,J15) -> 0 | K33: =SUM(J33,K15) -> 0 | L33: =SUM(K33,L15) -> 0 | M33: =SUM(L33,M15) -> 0 | ... P33: =SUM(O33,P15) -> 0
... D35: Ann | E35: =E17 -> 0 | F35: =SUM(E35,F17) -> 0 | G35: =SUM(F35,G17) -> 0 | H35: =SUM(G35,H17) -> 0 | I35: =SUM(H35,I17) -> 0 | J35: =SUM(I35,J17) -> 0 | K35: =SUM(J35,K17) -> 0 | L35: =SUM(K35,L17) -> 0 | M35: =SUM(L35,M17) -> 0 | ... P35: =SUM(O35,P17) -> 0

Sheet Membership
A1: Membership
A2: Name | B2: Member NO. | C2: Contact | D2: Next Of Kin | E2: Kin Contact
A3: Eric | B3: =IF(A3<>"","KAW-STAF-"&TEXT(ROW()-2,"000"),"") -> KAW-STAF-001
A4: Ethel | B4: =IF(A4<>"","KAW-STAF-"&TEXT(ROW()-2,"000"),"") -> KAW-STAF-002
A5: Mary | B5: =IF(A5<>"","KAW-STAF-"&TEXT(ROW()-2,"000"),"") -> KAW-STAF-003
A6: Isaac | B6: =IF(A6<>"","KAW-STAF-"&TEXT(ROW()-2,"000"),"") -> KAW-STAF-004
A7: Ruth | B7: =IF(A7<>"","KAW-STAF-"&TEXT(ROW()-2,"000"),"") -> KAW-STAF-005
A8: Eric.N | B8: =IF(A8<>"","KAW-STAF-"&TEXT(ROW()-2,"000"),"") -> KAW-STAF-006
A9: Daniel | B9: =IF(A9<>"","KAW-STAF-"&TEXT(ROW()-2,"000"),"") -> KAW-STAF-007
A10: Casmir | B10: =IF(A10<>"","KAW-STAF-"&TEXT(ROW()-2,"000"),"") -> KAW-STAF-008
A11: Phanice | B11: =IF(A11<>"","KAW-STAF-"&TEXT(ROW()-2,"000"),"") -> KAW-STAF-009
A12: Duncan | B12: =IF(A12<>"","KAW-STAF-"&TEXT(ROW()-2,"000"),"") -> KAW-STAF-010
A13: Allan | B13: =IF(A13<>"","KAW-STAF-"&TEXT(ROW()-2,"000"),"") -> KAW-STAF-011
A14: Colince | B14: =IF(A14<>"","KAW-STAF-"&TEXT(ROW()-2,"000"),"") -> KAW-STAF-012
... A16: Ann | B16: =IF(A16<>"","KAW-STAF-"&TEXT(ROW()-2,"000"),"") -> KAW-STAF-014

Sheet Loan
A1: Disbursment Date | B1: Loan Number | C1: Member Names | D1: Amount applied | E1: Period | F1: Total Payable | G1: Montly Installments | H1: Amount Paid | I1: Loan Balance | J1: Loan Status
B2: =IF(D2<>"","KAW-LN-"&TEXT(ROW()-1,"000"),"") -> KAW-LN-001 | C2: Eric | D2: 51000 | E2: 2 | F2: =IF(D2<=50000,D2*E2*0.05,D2*E2*0.04)+D2 -> 55080 | G2: =F2/E2 -> 27540 | H2: 27540 | I2: =G2-H2 -> 0 | J2: =IF(I2>1,"Active","Paid") -> Paid
B3: =IF(D3<>"","KAW-LN-"&TEXT(ROW()-1,"000"),"") -> KAW-LN-002 | C3: Ethel | D3: 9000
B4: =IF(D4<>"","KAW-LN-"&TEXT(ROW()-1,"000"),"")
B5: =IF(D5<>"","KAW-LN-"&TEXT(ROW()-1,"000"),"")
B6: =IF(D6<>"","KAW-LN-"&TEXT(ROW()-1,"000"),"")
B7: =IF(D7<>"","KAW-LN-"&TEXT(ROW()-1,"000"),"")
B8: =IF(D8<>"","KAW-LN-"&TEXT(ROW()-1,"000"),"")
B9: =IF(D9<>"","KAW-LN-"&TEXT(ROW()-1,"000"),"")
B10: =IF(D10<>"","KAW-LN-"&TEXT(ROW()-1,"000"),"")
B11: =IF(D11<>"","KAW-LN-"&TEXT(ROW()-1,"000"),"")
B12: =IF(D12<>"","KAW-LN-"&TEXT(ROW()-1,"000"),"")
B13: =IF(D13<>"","KAW-LN-"&TEXT(ROW()-1,"000"),"")
B14: =IF(D14<>"","KAW-LN-"&TEXT(ROW()-1,"000"),"")
B15: =IF(D15<>"","KAW-LN-"&TEXT(ROW()-1,"000"),"")
... B33: =IF(D33<>"","KAW-LN-"&TEXT(ROW()-1,"000"),"")

Sheet Data Collection
B2: Savings | G2: Loans Input
B3: Name | G3: Name
B6: Amount | C6: 2 | G6: Amount | H6: 787
G8: Loan Number
B9: Date | C9: =IF(C6>1,TODAY()," ") -> 46265
G10: Date | H10: =IF(H6>1,TODAY()," ") -> 46265
B11: Name | C11: =C3 -> 0
B12: Amount | C12: =C6 -> 2 | G12: Name | H12: =H3 -> 0
B13: Date | C13: =C9 -> 46265 | G13: Amount | H13: =H6 -> 787
G14: Loan Number | H14: =H8 -> 0
G15: Date | H15: =H10 -> 46265

Sheet LOANS
B3: Monthly Loan Book
C4: JAN | D4: FEB | E4: MAR | F4: APR | G4: MAY | H4: JUN | I4: JUL | J4: AUG | K4: SEP | L4: OCT | M4: NOV | N4: DEC
B5: Eric
B6: Amount | L6: 2
B7: period | C7: 2 | D7: 4 | E7: 0 | F7: 0 | G7: 0 | H7: 0 | I7: 0 | J7: 0 | K7: 0 | L7: 0 | M7: 0 | N7: 0
B8: Total pay | C8: =IF(C6<=50000,C6*0.05*C7,C6*0.04*C7) -> 0 | D8: =IF(D6<=50000,D6*0.05*D7,D6*0.04*D7) -> 0 | E8: =IF(E6<=50000,E6*0.05*E7,E6*0.04*E7) -> 0 | F8: =IF(F6<=50000,F6*0.05*F7,F6*0.04*F7) -> 0 | G8: =IF(G6<=50000,G6*0.05*G7,G6*0.04*G7) -> 0 | H8: =IF(H6<=50000,H6*0.05*H7,H6*0.04*H7) -> 0 | I8: =IF(I6<=50000,I6*0.05*I7,I6*0.04*I7) -> 0 | J8: =IF(J6<=50000,J6*0.05*J7,J6*0.04*J7) -> 0 | ... N8: =IF(N6<=50000,N6*0.05*N7,N6*0.04*N7) -> 0
B9: Ethel
B10: Amount
B11: period | C11: 3 | D11: 0 | E11: 0 | F11: 0 | G11: 0 | H11: 0 | I11: 3 | J11: 0 | K11: 0 | L11: 0 | M11: 0 | N11: 0
B12: Total pay | C12: =IF(C10<=50000,C10*0.05*C11,C10*0.04*C11) -> 0 | D12: =IF(D10<=50000,D10*0.05*D11,D10*0.04*D11) -> 0 | E12: =IF(E10<=50000,E10*0.05*E11,E10*0.04*E11) -> 0 | F12: =IF(F10<=50000,F10*0.05*F11,F10*0.04*F11) -> 0 | G12: =IF(G10<=50000,G10*0.05*G11,G10*0.04*G11) -> 0 | H12: =IF(H10<=50000,H10*0.05*H11,H10*0.04*H11) -> 0 | I12: =IF(I10<=50000,I10*0.05*I11,I10*0.04*I11) -> 0 | J12: =IF(J10<=50000,J10*0.05*J11,J10*0.04*J11) -> 0 | ... N12: =IF(N10<=50000,N10*0.05*N11,N10*0.04*N11) -> 0
B14: Mary
B15: Amount
B16: period | C16: 0 | D16: 3 | E16: 0 | F16: 0 | G16: 0 | H16: 0 | I16: 0 | J16: 0 | K16: 0 | L16: 0 | M16: 5 | N16: 0
B17: Total pay | C17: =IF(C15<=50000,C15*0.05*C16,C15*0.04*C16) -> 0 | D17: =IF(D15<=50000,D15*0.05*D16,D15*0.04*D16) -> 0 | E17: =IF(E15<=50000,E15*0.05*E16,E15*0.04*E16) -> 0 | F17: =IF(F15<=50000,F15*0.05*F16,F15*0.04*F16) -> 0 | G17: =IF(G15<=50000,G15*0.05*G16,G15*0.04*G16) -> 0 | H17: =IF(H15<=50000,H15*0.05*H16,H15*0.04*H16) -> 0 | I17: =IF(I15<=50000,I15*0.05*I16,I15*0.04*I16) -> 0 | J17: =IF(J15<=50000,J15*0.05*J16,J15*0.04*J16) -> 0 | ... N17: =IF(N15<=50000,N15*0.05*N16,N15*0.04*N16) -> 0
B19: Isaac
B20: Amount | C20: 40000 | D20: 45000 | E20: 30000 | F20: 60000 | G20: 52000 | I20: 50500 | J20: 50050
B21: period | C21: 1 | D21: 1 | E21: 1 | F21: 1 | G21: 1 | H21: 2 | I21: 1 | J21: 1 | K21: 0 | L21: 2 | M21: 0 | N21: 0
B22: Total pay | C22: =IF(C20<=50000,C20*0.05*C21,C20*0.04*C21) -> 2000 | D22: =IF(D20<=50000,D20*0.05*D21,D20*0.04*D21) -> 2250 | E22: =IF(E20<=50000,E20*0.05*E21,E20*0.04*E21) -> 1500 | F22: =IF(F20<=50000,F20*0.05*F21,F20*0.04*F21) -> 2400 | G22: =IF(G20<=50000,G20*0.05*G21,G20*0.04*G21) -> 2080 | H22: =IF(H20<=50000,H20*0.05*H21,H20*0.04*H21) -> 0 | I22: =IF(I20<=50000,I20*0.05*I21,I20*0.04*I21) -> 2020 | J22: =IF(J20<=50000,J20*0.05*J21,J20*0.04*J21) -> 2002 | ... N22: =IF(N20<=50000,N20*0.05*N21,N20*0.04*N21) -> 0
B23: P.M pay | C23: =IFERROR(SUM(C20,C22)/C21,0) -> 42000 | D23: =IFERROR(SUM(D20,D22)/D21,0) -> 47250 | E23: =IFERROR(SUM(E20,E22)/E21,0) -> 31500 | F23: =IFERROR(SUM(F20,F22)/F21,0) -> 62400 | G23: =IFERROR(SUM(G20,G22)/G21,0) -> 54080 | H23: =IFERROR(SUM(H20,H22)/H21,0) -> 0 | I23: =IFERROR(SUM(I20,I22)/I21,0) -> 52520 | J23: =IFERROR(SUM(J20,J22)/J21,0) -> 52052 | ... N23: =IFERROR(SUM(N20,N22)/N21,0) -> 0
B24: Ruth
B25: Amount
B26: period | C26: 0 | D26: 0 | E26: 2 | F26: 0 | G26: 0 | H26: 0 | I26: 0 | J26: 0 | K26: 0 | L26: 0 | M26: 0 | N26: 0
B27: Total pay | C27: =IF(C25<=50000,C25*0.05*C26,C25*0.04*C26) -> 0 | D27: =IF(D25<=50000,D25*0.05*D26,D25*0.04*D26) -> 0 | E27: =IF(E25<=50000,E25*0.05*E26,E25*0.04*E26) -> 0 | F27: =IF(F25<=50000,F25*0.05*F26,F25*0.04*F26) -> 0 | G27: =IF(G25<=50000,G25*0.05*G26,G25*0.04*G26) -> 0 | H27: =IF(H25<=50000,H25*0.05*H26,H25*0.04*H26) -> 0 | I27: =IF(I25<=50000,I25*0.05*I26,I25*0.04*I26) -> 0 | J27: =IF(J25<=50000,J25*0.05*J26,J25*0.04*J26) -> 0 | ... N27: =IF(N25<=50000,N25*0.05*N26,N25*0.04*N26) -> 0
B28: Eric.N
B29: Amount
B30: period | C30: 0 | D30: 0 | E30: 5 | F30: 0 | G30: 0 | H30: 0 | I30: 0 | J30: 0 | K30: 0 | L30: 0 | M30: 0 | N30: 0
B31: Total pay | C31: =IF(C29<=50000,C29*0.05*C30,C29*0.04*C30) -> 0 | D31: =IF(D29<=50000,D29*0.05*D30,D29*0.04*D30) -> 0 | E31: =IF(E29<=50000,E29*0.05*E30,E29*0.04*E30) -> 0 | F31: =IF(F29<=50000,F29*0.05*F30,F29*0.04*F30) -> 0 | G31: =IF(G29<=50000,G29*0.05*G30,G29*0.04*G30) -> 0 | H31: =IF(H29<=50000,H29*0.05*H30,H29*0.04*H30) -> 0 | I31: =IF(I29<=50000,I29*0.05*I30,I29*0.04*I30) -> 0 | J31: =IF(J29<=50000,J29*0.05*J30,J29*0.04*J30) -> 0 | ... N31: =IF(N29<=50000,N29*0.05*N30,N29*0.04*N30) -> 0
B32: Daniel
B33: Amount
B34: period | C34: 0 | D34: 0 | E34: 0 | F34: 0 | G34: 0 | H34: 0 | I34: 0 | J34: 0 | K34: 0 | L34: 0 | M34: 0 | N34: 0
B35: Total pay | C35: =IF(C33<=50000,C33*0.05*C34,C33*0.04*C34) -> 0 | D35: =IF(D33<=50000,D33*0.05*D34,D33*0.04*D34) -> 0 | E35: =IF(E33<=50000,E33*0.05*E34,E33*0.04*E34) -> 0 | F35: =IF(F33<=50000,F33*0.05*F34,F33*0.04*F34) -> 0 | G35: =IF(G33<=50000,G33*0.05*G34,G33*0.04*G34) -> 0 | H35: =IF(H33<=50000,H33*0.05*H34,H33*0.04*H34) -> 0 | I35: =IF(I33<=50000,I33*0.05*I34,I33*0.04*I34) -> 0 | J35: =IF(J33<=50000,J33*0.05*J34,J33*0.04*J34) -> 0 | ... N35: =IF(N33<=50000,N33*0.05*N34,N33*0.04*N34) -> 0
B36: Casmir
B37: Amount
B38: period | C38: 0 | D38: 0 | E38: 0 | F38: 0 | G38: 0 | H38: 1 | I38: 5 | J38: 0 | K38: 0 | L38: 0 | M38: 1 | N38: 0
B39: Total pay | C39: =IF(C37<=50000,C37*0.05*C38,C37*0.04*C38) -> 0 | D39: =IF(D37<=50000,D37*0.05*D38,D37*0.04*D38) -> 0 | E39: =IF(E37<=50000,E37*0.05*E38,E37*0.04*E38) -> 0 | F39: =IF(F37<=50000,F37*0.05*F38,F37*0.04*F38) -> 0 | G39: =IF(G37<=50000,G37*0.05*G38,G37*0.04*G38) -> 0 | H39: =IF(H37<=50000,H37*0.05*H38,H37*0.04*H38) -> 0 | I39: =IF(I37<=50000,I37*0.05*I38,I37*0.04*I38) -> 0 | J39: =IF(J37<=50000,J37*0.05*J38,J37*0.04*J38) -> 0 | ... N39: =IF(N37<=50000,N37*0.05*N38,N37*0.04*N38) -> 0
B40: Phanice
B41: Amount
B42: period | C42: 2 | D42: 0 | E42: 0 | F42: 0 | G42: 4 | H42: 0 | I42: 0 | J42: 2 | K42: 0 | L42: 0 | M42: 0 | N42: 0
B43: Total pay | C43: =IF(C41<=50000,C41*0.05*C42,C41*0.04*C42) -> 0 | D43: =IF(D41<=50000,D41*0.05*D42,D41*0.04*D42) -> 0 | E43: =IF(E41<=50000,E41*0.05*E42,E41*0.04*E42) -> 0 | F43: =IF(F41<=50000,F41*0.05*F42,F41*0.04*F42) -> 0 | G43: =IF(G41<=50000,G41*0.05*G42,G41*0.04*G42) -> 0 | H43: =IF(H41<=50000,H41*0.05*H42,H41*0.04*H42) -> 0 | I43: =IF(I41<=50000,I41*0.05*I42,I41*0.04*I42) -> 0 | J43: =IF(J41<=50000,J41*0.05*J42,J41*0.04*J42) -> 0 | ... N43: =IF(N41<=50000,N41*0.05*N42,N41*0.04*N42) -> 0
B44: Duncan
...

Sheet INCOME
C2: WELFARE INCOME CALCULATIONS
C4: Individual total loans | F4: Eligibilty | H4: Monthly Income | M4: Statement of Cashflow
C5: Eric | D5: =SUM(LOANS!C6:N6) -> 2 | F5: =IF(SAVING!P22<=INCOME!D5,"YES","NO") -> YES | H5: JAN | I5: =SUM(LOANS!C8,LOANS!C12,LOANS!C17,LOANS!C22,LOANS!C27,LOANS!C31,LOANS!C35,LOANS!C39,LOANS!C43,LOANS!C47,LOANS!C51,LOANS!C55) -> 2000 | M5: As at 31 Dec 2025
C6: Ethel | D6: =SUM(LOANS!C10:N10) -> 0 | F6: =IF(SAVING!P23<=INCOME!D6,"YES","NO") -> YES | H6: FEB | I6: =SUM(LOANS!D8,LOANS!D12,LOANS!D17,LOANS!D22,LOANS!D27,LOANS!D31,LOANS!D35,LOANS!D39,LOANS!D43,LOANS!D47,LOANS!D51,LOANS!D55) -> 2250 | M6: Bal b/f | O6: 3434
C7: Mary | D7: =SUM(LOANS!C15:N15) -> 0 | F7: =IF(SAVING!P24<=INCOME!D7,"YES","NO") -> YES | H7: MAR | I7: =SUM(LOANS!E8,LOANS!E12,LOANS!E17,LOANS!E22,LOANS!E27,LOANS!E31,LOANS!E35,LOANS!E39,LOANS!E43,LOANS!E47,LOANS!E51,LOANS!E55) -> 1500 | M7: Total saving | O7: =SUM(SAVING!P22:P35) -> 89000
C8: Isaac | D8: =SUM(LOANS!C20:N20) -> 327550 | F8: =IF(SAVING!P25<=INCOME!D8,"YES","NO") -> YES | H8: APR | I8: =SUM(LOANS!F8,LOANS!F12,LOANS!F17,LOANS!F22,LOANS!F27,LOANS!F31,LOANS!F35,LOANS!F39,LOANS!F43,LOANS!F47,LOANS!F51,LOANS!F55) -> 2400 | M8: Total intrest income | O8: =SUM(I5:I16) -> 14252
C9: Ruth | D9: =SUM(LOANS!C25:N25) -> 0 | F9: =IF(SAVING!P26<=INCOME!D9,"YES","NO") -> YES | H9: MAY | I9: =SUM(LOANS!G8,LOANS!G12,LOANS!G17,LOANS!G22,LOANS!G27,LOANS!G31,LOANS!G35,LOANS!G39,LOANS!G43,LOANS!G47,LOANS!G51,LOANS!G55) -> 2080 | M9: Fees/penalty income | O9: 45
C10: Eric.N | D10: =SUM(LOANS!C29:N29) -> 0 | F10: =IF(SAVING!P27<=INCOME!D10,"YES","NO") -> YES | H10: JUN | I10: =SUM(LOANS!H8,LOANS!H12,LOANS!H17,LOANS!H22,LOANS!H27,LOANS!H31,LOANS!H35,LOANS!H39,LOANS!H43,LOANS!H47,LOANS!H51,LOANS!H55) -> 0 | M10: Total income | O10: =SUM(O6:O9) -> 106731
C11: Daniel | D11: =SUM(LOANS!C33:N33) -> 0 | F11: =IF(SAVING!P28<=INCOME!D11,"YES","NO") -> YES | H11: JUL | I11: =SUM(LOANS!I8,LOANS!I12,LOANS!I17,LOANS!I22,LOANS!I27,LOANS!I31,LOANS!I35,LOANS!I39,LOANS!I43,LOANS!I47,LOANS!I51,LOANS!I55) -> 2020 | M11: Less Admn Cost | O11: 6777
C12: Casmir | D12: =SUM(LOANS!C37:N37) -> 0 | F12: =IF(SAVING!P29<=INCOME!D12,"YES","NO") -> YES | H12: AUG | I12: =SUM(LOANS!J8,LOANS!J12,LOANS!J17,LOANS!J22,LOANS!J27,LOANS!J31,LOANS!J35,LOANS!J39,LOANS!J43,LOANS!J47,LOANS!J51,LOANS!J55) -> 2002
C13: Phanice | D13: =SUM(LOANS!C41:N41) -> 0 | F13: =IF(SAVING!P30<=INCOME!D13,"YES","NO") -> YES | H13: SEP | I13: =SUM(LOANS!K8,LOANS!K12,LOANS!K17,LOANS!K22,LOANS!K27,LOANS!K31,LOANS!K35,LOANS!K39,LOANS!K43,LOANS!K47,LOANS!K51,LOANS!K55) -> 0 | M13: Dr.Member accounts | O13: =O10-O11 -> 99954
C14: Duncan | D14: =SUM(LOANS!C45:N45) -> 0 | F14: =IF(SAVING!P31<=INCOME!D14,"YES","NO") -> YES | H14: OCT | I14: =SUM(LOANS!L8,LOANS!L12,LOANS!L17,LOANS!L22,LOANS!L27,LOANS!L31,LOANS!L35,LOANS!L39,LOANS!L43,LOANS!L47,LOANS!L51,LOANS!L55) -> 0 | M14: Bank Acc.Balance | O14: 559638
C15: Allan | D15: =SUM(LOANS!C49:N49) -> 0 | F15: =IF(SAVING!P32<=INCOME!D15,"YES","NO") -> YES | H15: NOV | I15: =SUM(LOANS!M8,LOANS!M12,LOANS!M17,LOANS!M22,LOANS!M27,LOANS!M31,LOANS!M35,LOANS!M39,LOANS!M43,LOANS!M47,LOANS!M51,LOANS!M55) -> 0 | M15: Deficit/Suplus | O15: =(O14-O13) -> 459684
C16: Colince | D16: =SUM(LOANS!C53:N53) -> 0 | F16: =IF(SAVING!P33<=INCOME!D16,"YES","NO") -> YES | H16: DEC | I16: =SUM(LOANS!N8,LOANS!N12,LOANS!N17,LOANS!N22,LOANS!N27,LOANS!N31,LOANS!N35,LOANS!N39,LOANS!N43,LOANS!N47,LOANS!N51,LOANS!N55) -> 0
C17: Florence | D17: =SUM(LOANS!C57:N57) -> 0 | F17: =IF(SAVING!P34<=INCOME!D17,"YES","NO") -> YES
C18: Ann | D18: =SUM(LOANS!C61:N61) -> 0 | F18: =IF(SAVING!P35<=INCOME!D18,"YES","NO") -> YES
C20: Monthly Member Proportionate share ratio
D21: JAN | E21: FEB | F21: MAR | G21: APR | H21: MAY | I21: JUN | J21: JUL | K21: AUG | L21: SEP | M21: OCT | N21: NOV | O21: DEC
C22: Eric | D22: =IFERROR(IF(F5="YES",SAVING!E22/SUMIF($F$5:$F$18,"YES",SAVING!$E$22:$E$35),0),0) -> 0 | E22: =IFERROR(IF(F5="YES",SAVING!F22/SUMIF(INCOME!$F$5:$F$18,"YES",SAVING!$F$22:$F$35),0),0) -> 0 | F22: =IFERROR(IF(F5="YES",SAVING!G22/SUMIF(INCOME!$F$5:$F$18,"YES",SAVING!$G$22:$G$35),0),0) -> 0 | G22: =IFERROR(IF(F5="YES",SAVING!H22/SUMIF(INCOME!$F$5:$F$18,"YES",SAVING!$H$22:$H$35),0),0) -> 0 | H22: =IFERROR(IF(F5="YES",SAVING!I22/SUMIF(INCOME!$F$5:$F$18,"YES",SAVING!$I$22:$I$35),0),0) -> 0 | I22: =IFERROR(IF(F5="YES",SAVING!J22/SUMIF(INCOME!$F$5:$F$18,"YES",SAVING!$J$22:$J$35),0),0) -> 0 | J22: =IFERROR(IF(F5="YES",SAVING!K22/SUMIF(INCOME!$F$5:$F$18,"YES",SAVING!$K$22:$K$35),0),0) -> 0 | K22: =IFERROR(IF(F5="YES",SAVING!L22/SUMIF(INCOME!$F$5:$F$18,"YES",SAVING!$L$22:$L$35),0),0) -> 0 | L22: =IFERROR(IF(F5="YES",SAVING!M22/SUMIF(INCOME!$F$5:$F$18,"YES",SAVING!$M$22:$M$36),0),0) -> 0 | M22: =IFERROR(IF(F5="YES",SAVING!N22/SUMIF(INCOME!$F$5:$F$18,"YES",SAVING!$N$22:$N$35),0),0) -> 0 | N22: =IFERROR(IF(F5="YES",SAVING!O22/SUMIF(INCOME!$F$5:$F$18,"YES",SAVING!$O$22:$O$35),0),0) -> 0 | O22: =IFERROR(IF(F5="YES",SAVING!P22/SUMIF(INCOME!$F$5:$F$178,"YES",SAVING!$P$22:$P$35),0),0) -> 0
C23: Ethel | D23: =IFERROR(IF(F6="YES",SAVING!E23/SUMIF($F$5:$F$18,"YES",SAVING!$E$22:$E$35),0),0) -> 0 | E23: =IFERROR(IF(F6="YES",SAVING!F23/SUMIF(INCOME!$F$5:$F$18,"YES",SAVING!$F$22:$F$35),0),0) -> 0 | F23: =IFERROR(IF(F6="YES",SAVING!G23/SUMIF(INCOME!$F$5:$F$18,"YES",SAVING!$G$22:$G$35),0),0) -> 0 | G23: =IFERROR(IF(F6="YES",SAVING!H23/SUMIF(INCOME!$F$5:$F$18,"YES",SAVING!$H$22:$H$35),0),0) -> 0 | H23: =IFERROR(IF(F6="YES",SAVING!I23/SUMIF(INCOME!$F$5:$F$18,"YES",SAVING!$I$22:$I$35),0),0) -> 0 | I23: =IFERROR(IF(F6="YES",SAVING!J23/SUMIF(INCOME!$F$5:$F$18,"YES",SAVING!$J$22:$J$35),0),0) -> 0 | J23: =IFERROR(IF(F6="YES",SAVING!K23/SUMIF(INCOME!$F$5:$F$18,"YES",SAVING!$K$22:$K$35),0),0) -> 0 | K23: =IFERROR(IF(F6="YES",SAVING!L23/SUMIF(INCOME!$F$5:$F$18,"YES",SAVING!$L$22:$L$35),0),0) -> 0 | L23: =IFERROR(IF(F6="YES",SAVING!M23/SUMIF(INCOME!$F$5:$F$18,"YES",SAVING!$M$22:$M$36),0),0) -> 0 | M23: =IFERROR(IF(F6="YES",SAVING!N23/SUMIF(INCOME!$F$5:$F$18,"YES",SAVING!$N$22:$N$35),0),0) -> 0 | N23: =IFERROR(IF(F6="YES",SAVING!O23/SUMIF(INCOME!$F$5:$F$18,"YES",SAVING!$O$22:$O$35),0),0) -> 0 | O23: =IFERROR(IF(F6="YES",SAVING!P23/SUMIF(INCOME!$F$5:$F$178,"YES",SAVING!$P$22:$P$35),0),0) -> 0
C24: Mary | D24: =IFERROR(IF(F7="YES",SAVING!E24/SUMIF($F$5:$F$18,"YES",SAVING!$E$22:$E$35),0),0) -> 0 | E24: =IFERROR(IF(F7="YES",SAVING!F24/SUMIF(INCOME!$F$5:$F$18,"YES",SAVING!$F$22:$F$35),0),0) -> 0 | F24: =IFERROR(IF(F7="YES",SAVING!G24/SUMIF(INCOME!$F$5:$F$18,"YES",SAVING!$G$22:$G$35),0),0) -> 0 | G24: =IFERROR(IF(F7="YES",SAVING!H24/SUMIF(INCOME!$F$5:$F$18,"YES",SAVING!$H$22:$H$35),0),0) -> 0 | H24: =IFERROR(IF(F7="YES",SAVING!I24/SUMIF(INCOME!$F$5:$F$18,"YES",SAVING!$I$22:$I$35),0),0) -> 0 | I24: =IFERROR(IF(F7="YES",SAVING!J24/SUMIF(INCOME!$F$5:$F$18,"YES",SAVING!$J$22:$J$35),0),0) -> 0 | J24: =IFERROR(IF(F7="YES",SAVING!K24/SUMIF(INCOME!$F$5:$F$18,"YES",SAVING!$K$22:$K$35),0),0) -> 0 | K24: =IFERROR(IF(F7="YES",SAVING!L24/SUMIF(INCOME!$F$5:$F$18,"YES",SAVING!$L$22:$L$35),0),0) -> 0 | L24: =IFERROR(IF(F7="YES",SAVING!M24/SUMIF(INCOME!$F$5:$F$18,"YES",SAVING!$M$22:$M$36),0),0) -> 0 | M24: =IFERROR(IF(F7="YES",SAVING!N24/SUMIF(INCOME!$F$5:$F$18,"YES",SAVING!$N$22:$N$35),0),0) -> 0 | N24: =IFERROR(IF(F7="YES",SAVING!O24/SUMIF(INCOME!$F$5:$F$18,"YES",SAVING!$O$22:$O$35),0),0) -> 0 | O24: =IFERROR(IF(F7="YES",SAVING!P24/SUMIF(INCOME!$F$5:$F$178,"YES",SAVING!$P$22:$P$35),0),0) -> 0
C25: Isaac | D25: =IFERROR(IF(F8="YES",SAVING!E25/SUMIF($F$5:$F$18,"YES",SAVING!$E$22:$E$35),0),0) -> 1 | E25: =IFERROR(IF(F8="YES",SAVING!F25/SUMIF(INCOME!$F$5:$F$18,"YES",SAVING!$F$22:$F$35),0),0) -> 1 | F25: =IFERROR(IF(F8="YES",SAVING!G25/SUMIF(INCOME!$F$5:$F$18,"YES",SAVING!$G$22:$G$35),0),0) -> 1 | G25: =IFERROR(IF(F8="YES",SAVING!H25/SUMIF(INCOME!$F$5:$F$18,"YES",SAVING!$H$22:$H$35),0),0) -> 1 | H25: =IFERROR(IF(F8="YES",SAVING!I25/SUMIF(INCOME!$F$5:$F$18,"YES",SAVING!$I$22:$I$35),0),0) -> 1 | I25: =IFERROR(IF(F8="YES",SAVING!J25/SUMIF(INCOME!$F$5:$F$18,"YES",SAVING!$J$22:$J$35),0),0) -> 1 | J25: =IFERROR(IF(F8="YES",SAVING!K25/SUMIF(INCOME!$F$5:$F$18,"YES",SAVING!$K$22:$K$35),0),0) -> 1 | K25: =IFERROR(IF(F8="YES",SAVING!L25/SUMIF(INCOME!$F$5:$F$18,"YES",SAVING!$L$22:$L$35),0),0) -> 1 | L25: =IFERROR(IF(F8="YES",SAVING!M25/SUMIF(INCOME!$F$5:$F$18,"YES",SAVING!$M$22:$M$36),0),0) -> 1 | M25: =IFERROR(IF(F8="YES",SAVING!N25/SUMIF(INCOME!$F$5:$F$18,"YES",SAVING!$N$22:$N$35),0),0) -> 1 | N25: =IFERROR(IF(F8="YES",SAVING!O25/SUMIF(INCOME!$F$5:$F$18,"YES",SAVING!$O$22:$O$35),0),0) -> 1 | O25: =IFERROR(IF(F8="YES",SAVING!P25/SUMIF(INCOME!$F$5:$F$178,"YES",SAVING!$P$22:$P$35),0),0) -> 1
C26: Ruth | D26: =IFERROR(IF(F9="YES",SAVING!E26/SUMIF($F$5:$F$18,"YES",SAVING!$E$22:$E$35),0),0) -> 0 | E26: =IFERROR(IF(F9="YES",SAVING!F26/SUMIF(INCOME!$F$5:$F$18,"YES",SAVING!$F$22:$F$35),0),0) -> 0 | F26: =IFERROR(IF(F9="YES",SAVING!G26/SUMIF(INCOME!$F$5:$F$18,"YES",SAVING!$G$22:$G$35),0),0) -> 0 | G26: =IFERROR(IF(F9="YES",SAVING!H26/SUMIF(INCOME!$F$5:$F$18,"YES",SAVING!$H$22:$H$35),0),0) -> 0 | H26: =IFERROR(IF(F9="YES",SAVING!I26/SUMIF(INCOME!$F$5:$F$18,"YES",SAVING!$I$22:$I$35),0),0) -> 0 | I26: =IFERROR(IF(F9="YES",SAVING!J26/SUMIF(INCOME!$F$5:$F$18,"YES",SAVING!$J$22:$J$35),0),0) -> 0 | J26: =IFERROR(IF(F9="YES",SAVING!K26/SUMIF(INCOME!$F$5:$F$18,"YES",SAVING!$K$22:$K$35),0),0) -> 0 | K26: =IFERROR(IF(F9="YES",SAVING!L26/SUMIF(INCOME!$F$5:$F$18,"YES",SAVING!$L$22:$L$35),0),0) -> 0 | L26: =IFERROR(IF(F9="YES",SAVING!M26/SUMIF(INCOME!$F$5:$F$18,"YES",SAVING!$M$22:$M$36),0),0) -> 0 | M26: =IFERROR(IF(F9="YES",SAVING!N26/SUMIF(INCOME!$F$5:$F$18,"YES",SAVING!$N$22:$N$35),0),0) -> 0 | N26: =IFERROR(IF(F9="YES",SAVING!O26/SUMIF(INCOME!$F$5:$F$18,"YES",SAVING!$O$22:$O$35),0),0) -> 0 | O26: =IFERROR(IF(F9="YES",SAVING!P26/SUMIF(INCOME!$F$5:$F$178,"YES",SAVING!$P$22:$P$35),0),0) -> 0
C27: Eric.N | D27: =IFERROR(IF(F10="YES",SAVING!E27/SUMIF($F$5:$F$18,"YES",SAVING!$E$22:$E$35),0),0) -> 0 | E27: =IFERROR(IF(F10="YES",SAVING!F27/SUMIF(INCOME!$F$5:$F$18,"YES",SAVING!$F$22:$F$35),0),0) -> 0 | F27: =IFERROR(IF(F10="YES",SAVING!G27/SUMIF(INCOME!$F$5:$F$18,"YES",SAVING!$G$22:$G$35),0),0) -> 0 | G27: =IFERROR(IF(F10="YES",SAVING!H27/SUMIF(INCOME!$F$5:$F$18,"YES",SAVING!$H$22:$H$35),0),0) -> 0 | H27: =IFERROR(IF(F10="YES",SAVING!I27/SUMIF(INCOME!$F$5:$F$18,"YES",SAVING!$I$22:$I$35),0),0) -> 0 | I27: =IFERROR(IF(F10="YES",SAVING!J27/SUMIF(INCOME!$F$5:$F$18,"YES",SAVING!$J$22:$J$35),0),0) -> 0 | J27: =IFERROR(IF(F10="YES",SAVING!K27/SUMIF(INCOME!$F$5:$F$18,"YES",SAVING!$K$22:$K$35),0),0) -> 0 | K27: =IFERROR(IF(F10="YES",SAVING!L27/SUMIF(INCOME!$F$5:$F$18,"YES",SAVING!$L$22:$L$35),0),0) -> 0 | L27: =IFERROR(IF(F10="YES",SAVING!M27/SUMIF(INCOME!$F$5:$F$18,"YES",SAVING!$M$22:$M$36),0),0) -> 0 | M27: =IFERROR(IF(F10="YES",SAVING!N27/SUMIF(INCOME!$F$5:$F$18,"YES",SAVING!$N$22:$N$35),0),0) -> 0 | N27: =IFERROR(IF(F10="YES",SAVING!O27/SUMIF(INCOME!$F$5:$F$18,"YES",SAVING!$O$22:$O$35),0),0) -> 0 | O27: =IFERROR(IF(F10="YES",SAVING!P27/SUMIF(INCOME!$F$5:$F$178,"YES",SAVING!$P$22:$P$35),0),0) -> 0
C28: Daniel | D28: =IFERROR(IF(F11="YES",SAVING!E28/SUMIF($F$5:$F$18,"YES",SAVING!$E$22:$E$35),0),0) -> 0 | E28: =IFERROR(IF(F11="YES",SAVING!F28/SUMIF(INCOME!$F$5:$F$18,"YES",SAVING!$F$22:$F$35),0),0) -> 0 | F28: =IFERROR(IF(F11="YES",SAVING!G28/SUMIF(INCOME!$F$5:$F$18,"YES",SAVING!$G$22:$G$35),0),0) -> 0 | G28: =IFERROR(IF(F11="YES",SAVING!H28/SUMIF(INCOME!$F$5:$F$18,"YES",SAVING!$H$22:$H$35),0),0) -> 0 | H28: =IFERROR(IF(F11="YES",SAVING!I28/SUMIF(INCOME!$F$5:$F$18,"YES",SAVING!$I$22:$I$35),0),0) -> 0 | I28: =IFERROR(IF(F11="YES",SAVING!J28/SUMIF(INCOME!$F$5:$F$18,"YES",SAVING!$J$22:$J$35),0),0) -> 0 | J28: =IFERROR(IF(F11="YES",SAVING!K28/SUMIF(INCOME!$F$5:$F$18,"YES",SAVING!$K$22:$K$35),0),0) -> 0 | K28: =IFERROR(IF(F11="YES",SAVING!L28/SUMIF(INCOME!$F$5:$F$18,"YES",SAVING!$L$22:$L$35),0),0) -> 0 | L28: =IFERROR(IF(F11="YES",SAVING!M28/SUMIF(INCOME!$F$5:$F$18,"YES",SAVING!$M$22:$M$36),0),0) -> 0 | M28: =IFERROR(IF(F11="YES",SAVING!N28/SUMIF(INCOME!$F$5:$F$18,"YES",SAVING!$N$22:$N$35),0),0) -> 0 | N28: =IFERROR(IF(F11="YES",SAVING!O28/SUMIF(INCOME!$F$5:$F$18,"YES",SAVING!$O$22:$O$35),0),0) -> 0 | O28: =IFERROR(IF(F11="YES",SAVING!P28/SUMIF(INCOME!$F$5:$F$178,"YES",SAVING!$P$22:$P$35),0),0) -> 0
C29: Casmir | D29: =IFERROR(IF(F12="YES",SAVING!E29/SUMIF($F$5:$F$18,"YES",SAVING!$E$22:$E$35),0),0) -> 0 | E29: =IFERROR(IF(F12="YES",SAVING!F29/SUMIF(INCOME!$F$5:$F$18,"YES",SAVING!$F$22:$F$35),0),0) -> 0 | F29: =IFERROR(IF(F12="YES",SAVING!G29/SUMIF(INCOME!$F$5:$F$18,"YES",SAVING!$G$22:$G$35),0),0) -> 0 | G29: =IFERROR(IF(F12="YES",SAVING!H29/SUMIF(INCOME!$F$5:$F$18,"YES",SAVING!$H$22:$H$35),0),0) -> 0 | H29: =IFERROR(IF(F12="YES",SAVING!I29/SUMIF(INCOME!$F$5:$F$18,"YES",SAVING!$I$22:$I$35),0),0) -> 0 | I29: =IFERROR(IF(F12="YES",SAVING!J29/SUMIF(INCOME!$F$5:$F$18,"YES",SAVING!$J$22:$J$35),0),0) -> 0 | J29: =IFERROR(IF(F12="YES",SAVING!K29/SUMIF(INCOME!$F$5:$F$18,"YES",SAVING!$K$22:$K$35),0),0) -> 0 | K29: =IFERROR(IF(F12="YES",SAVING!L29/SUMIF(INCOME!$F$5:$F$18,"YES",SAVING!$L$22:$L$35),0),0) -> 0 | L29: =IFERROR(IF(F12="YES",SAVING!M29/SUMIF(INCOME!$F$5:$F$18,"YES",SAVING!$M$22:$M$36),0),0) -> 0 | M29: =IFERROR(IF(F12="YES",SAVING!N29/SUMIF(INCOME!$F$5:$F$18,"YES",SAVING!$N$22:$N$35),0),0) -> 0 | N29: =IFERROR(IF(F12="YES",SAVING!O29/SUMIF(INCOME!$F$5:$F$18,"YES",SAVING!$O$22:$O$35),0),0) -> 0 | O29: =IFERROR(IF(F12="YES",SAVING!P29/SUMIF(INCOME!$F$5:$F$178,"YES",SAVING!$P$22:$P$35),0),0) -> 0
C30: Phanice | D30: =IFERROR(IF(F13="YES",SAVING!E30/SUMIF($F$5:$F$18,"YES",SAVING!$E$22:$E$35),0),0) -> 0 | E30: =IFERROR(IF(F13="YES",SAVING!F30/SUMIF(INCOME!$F$5:$F$18,"YES",SAVING!$F$22:$F$35),0),0) -> 0 | F30: =IFERROR(IF(F13="YES",SAVING!G30/SUMIF(INCOME!$F$5:$F$18,"YES",SAVING!$G$22:$G$35),0),0) -> 0 | G30: =IFERROR(IF(F13="YES",SAVING!H30/SUMIF(INCOME!$F$5:$F$18,"YES",SAVING!$H$22:$H$35),0),0) -> 0 | H30: =IFERROR(IF(F13="YES",SAVING!I30/SUMIF(INCOME!$F$5:$F$18,"YES",SAVING!$I$22:$I$35),0),0) -> 0 | I30: =IFERROR(IF(F13="YES",SAVING!J30/SUMIF(INCOME!$F$5:$F$18,"YES",SAVING!$J$22:$J$35),0),0) -> 0 | J30: =IFERROR(IF(F13="YES",SAVING!K30/SUMIF(INCOME!$F$5:$F$18,"YES",SAVING!$K$22:$K$35),0),0) -> 0 | K30: =IFERROR(IF(F13="YES",SAVING!L30/SUMIF(INCOME!$F$5:$F$18,"YES",SAVING!$L$22:$L$35),0),0) -> 0 | L30: =IFERROR(IF(F13="YES",SAVING!M30/SUMIF(INCOME!$F$5:$F$18,"YES",SAVING!$M$22:$M$36),0),0) -> 0 | M30: =IFERROR(IF(F13="YES",SAVING!N30/SUMIF(INCOME!$F$5:$F$18,"YES",SAVING!$N$22:$N$35),0),0) -> 0 | N30: =IFERROR(IF(F13="YES",SAVING!O30/SUMIF(INCOME!$F$5:$F$18,"YES",SAVING!$O$22:$O$35),0),0) -> 0 | O30: =IFERROR(IF(F13="YES",SAVING!P30/SUMIF(INCOME!$F$5:$F$178,"YES",SAVING!$P$22:$P$35),0),0) -> 0
C31: Duncan | D31: =IFERROR(IF(F14="YES",SAVING!E31/SUMIF($F$5:$F$18,"YES",SAVING!$E$22:$E$35),0),0) -> 0 | E31: =IFERROR(IF(F14="YES",SAVING!F31/SUMIF(INCOME!$F$5:$F$18,"YES",SAVING!$F$22:$F$35),0),0) -> 0 | F31: =IFERROR(IF(F14="YES",SAVING!G31/SUMIF(INCOME!$F$5:$F$18,"YES",SAVING!$G$22:$G$35),0),0) -> 0 | G31: =IFERROR(IF(F14="YES",SAVING!H31/SUMIF(INCOME!$F$5:$F$18,"YES",SAVING!$H$22:$H$35),0),0) -> 0 | H31: =IFERROR(IF(F14="YES",SAVING!I31/SUMIF(INCOME!$F$5:$F$18,"YES",SAVING!$I$22:$I$35),0),0) -> 0 | I31: =IFERROR(IF(F14="YES",SAVING!J31/SUMIF(INCOME!$F$5:$F$18,"YES",SAVING!$J$22:$J$35),0),0) -> 0 | J31: =IFERROR(IF(F14="YES",SAVING!K31/SUMIF(INCOME!$F$5:$F$18,"YES",SAVING!$K$22:$K$35),0),0) -> 0 | K31: =IFERROR(IF(F14="YES",SAVING!L31/SUMIF(INCOME!$F$5:$F$18,"YES",SAVING!$L$22:$L$35),0),0) -> 0 | L31: =IFERROR(IF(F14="YES",SAVING!M31/SUMIF(INCOME!$F$5:$F$18,"YES",SAVING!$M$22:$M$36),0),0) -> 0 | M31: =IFERROR(IF(F14="YES",SAVING!N31/SUMIF(INCOME!$F$5:$F$18,"YES",SAVING!$N$22:$N$35),0),0) -> 0 | N31: =IFERROR(IF(F14="YES",SAVING!O31/SUMIF(INCOME!$F$5:$F$18,"YES",SAVING!$O$22:$O$35),0),0) -> 0 | O31: =IFERROR(IF(F14="YES",SAVING!P31/SUMIF(INCOME!$F$5:$F$178,"YES",SAVING!$P$22:$P$35),0),0) -> 0
C32: Allan | D32: =IFERROR(IF(F15="YES",SAVING!E32/SUMIF($F$5:$F$18,"YES",SAVING!$E$22:$E$35),0),0) -> 0 | E32: =IFERROR(IF(F15="YES",SAVING!F32/SUMIF(INCOME!$F$5:$F$18,"YES",SAVING!$F$22:$F$35),0),0) -> 0 | F32: =IFERROR(IF(F15="YES",SAVING!G32/SUMIF(INCOME!$F$5:$F$18,"YES",SAVING!$G$22:$G$35),0),0) -> 0 | G32: =IFERROR(IF(F15="YES",SAVING!H32/SUMIF(INCOME!$F$5:$F$18,"YES",SAVING!$H$22:$H$35),0),0) -> 0 | H32: =IFERROR(IF(F15="YES",SAVING!I32/SUMIF(INCOME!$F$5:$F$18,"YES",SAVING!$I$22:$I$35),0),0) -> 0 | I32: =IFERROR(IF(F15="YES",SAVING!J32/SUMIF(INCOME!$F$5:$F$18,"YES",SAVING!$J$22:$J$35),0),0) -> 0 | J32: =IFERROR(IF(F15="YES",SAVING!K32/SUMIF(INCOME!$F$5:$F$18,"YES",SAVING!$K$22:$K$35),0),0) -> 0 | K32: =IFERROR(IF(F15="YES",SAVING!L32/SUMIF(INCOME!$F$5:$F$18,"YES",SAVING!$L$22:$L$35),0),0) -> 0 | L32: =IFERROR(IF(F15="YES",SAVING!M32/SUMIF(INCOME!$F$5:$F$18,"YES",SAVING!$M$22:$M$36),0),0) -> 0 | M32: =IFERROR(IF(F15="YES",SAVING!N32/SUMIF(INCOME!$F$5:$F$18,"YES",SAVING!$N$22:$N$35),0),0) -> 0 | N32: =IFERROR(IF(F15="YES",SAVING!O32/SUMIF(INCOME!$F$5:$F$18,"YES",SAVING!$O$22:$O$35),0),0) -> 0 | O32: =IFERROR(IF(F15="YES",SAVING!P32/SUMIF(INCOME!$F$5:$F$178,"YES",SAVING!$P$22:$P$35),0),0) -> 0
C33: Colince | D33: =IFERROR(IF(F16="YES",SAVING!E33/SUMIF($F$5:$F$18,"YES",SAVING!$E$22:$E$35),0),0) -> 0 | E33: =IFERROR(IF(F16="YES",SAVING!F33/SUMIF(INCOME!$F$5:$F$18,"YES",SAVING!$F$22:$F$35),0),0) -> 0 | F33: =IFERROR(IF(F16="YES",SAVING!G33/SUMIF(INCOME!$F$5:$F$18,"YES",SAVING!$G$22:$G$35),0),0) -> 0 | G33: =IFERROR(IF(F16="YES",SAVING!H33/SUMIF(INCOME!$F$5:$F$18,"YES",SAVING!$H$22:$H$35),0),0) -> 0 | H33: =IFERROR(IF(F16="YES",SAVING!I33/SUMIF(INCOME!$F$5:$F$18,"YES",SAVING!$I$22:$I$35),0),0) -> 0 | I33: =IFERROR(IF(F16="YES",SAVING!J33/SUMIF(INCOME!$F$5:$F$18,"YES",SAVING!$J$22:$J$35),0),0) -> 0 | J33: =IFERROR(IF(F16="YES",SAVING!K33/SUMIF(INCOME!$F$5:$F$18,"YES",SAVING!$K$22:$K$35),0),0) -> 0 | K33: =IFERROR(IF(F16="YES",SAVING!L33/SUMIF(INCOME!$F$5:$F$18,"YES",SAVING!$L$22:$L$35),0),0) -> 0 | L33: =IFERROR(IF(F16="YES",SAVING!M33/SUMIF(INCOME!$F$5:$F$18,"YES",SAVING!$M$22:$M$36),0),0) -> 0 | M33: =IFERROR(IF(F16="YES",SAVING!N33/SUMIF(INCOME!$F$5:$F$18,"YES",SAVING!$N$22:$N$35),0),0) -> 0 | N33: =IFERROR(IF(F16="YES",SAVING!O33/SUMIF(INCOME!$F$5:$F$18,"YES",SAVING!$O$22:$O$35),0),0) -> 0 | O33: =IFERROR(IF(F16="YES",SAVING!P33/SUMIF(INCOME!$F$5:$F$178,"YES",SAVING!$P$22:$P$35),0),0) -> 0
... C35: Ann | D35: =IFERROR(IF(F18="YES",SAVING!E35/SUMIF($F$5:$F$18,"YES",SAVING!$E$22:$E$35),0),0) -> 0 | E35: =IFERROR(IF(F18="YES",SAVING!F35/SUMIF(INCOME!$F$5:$F$18,"YES",SAVING!$F$22:$F$35),0),0) -> 0 | F35: =IFERROR(IF(F18="YES",SAVING!G35/SUMIF(INCOME!$F$5:$F$18,"YES",SAVING!$G$22:$G$35),0),0) -> 0 | G35: =IFERROR(IF(F18="YES",SAVING!H35/SUMIF(INCOME!$F$5:$F$18,"YES",SAVING!$H$22:$H$35),0),0) -> 0 | H35: =IFERROR(IF(F18="YES",SAVING!I35/SUMIF(INCOME!$F$5:$F$18,"YES",SAVING!$I$22:$I$35),0),0) -> 0 | I35: =IFERROR(IF(F18="YES",SAVING!J35/SUMIF(INCOME!$F$5:$F$18,"YES",SAVING!$J$22:$J$35),0),0) -> 0 | J35: =IFERROR(IF(F18="YES",SAVING!K35/SUMIF(INCOME!$F$5:$F$18,"YES",SAVING!$K$22:$K$35),0),0) -> 0 | K35: =IFERROR(IF(F18="YES",SAVING!L35/SUMIF(INCOME!$F$5:$F$18,"YES",SAVING!$L$22:$L$35),0),0) -> 0 | L35: =IFERROR(IF(F18="YES",SAVING!M35/SUMIF(INCOME!$F$5:$F$18,"YES",SAVING!$M$22:$M$36),0),0) -> 0 | M35: =IFERROR(IF(F18="YES",SAVING!N35/SUMIF(INCOME!$F$5:$F$18,"YES",SAVING!$N$22:$N$35),0),0) -> 0 | N35: =IFERROR(IF(F18="YES",SAVING!O35/SUMIF(INCOME!$F$5:$F$18,"YES",SAVING!$O$22:$O$35),0),0) -> 0 | O35: =IFERROR(IF(F18="YES",SAVING!P35/SUMIF(INCOME!$F$5:$F$178,"YES",SAVING!$P$22:$P$35),0),0) -> 0
C37: Monthly Member Dividend Earnings
D38: JAN | E38: FEB | F38: MAR | G38: APR | H38: MAY | I38: JUN | J38: JUL | K38: AUG | L38: SEP | M38: OCT | N38: NOV | O38: DEC
C39: Eric | D39: =IFERROR(D22*$I$5,0) -> 0 | E39: =IFERROR(E22*$I$6,0) -> 0 | F39: =IFERROR(F22*$I$7,0) -> 0 | G39: =IFERROR(G22*$I$8,0) -> 0 | H39: =IFERROR(H22*$I$9,0) -> 0 | I39: =IFERROR(I22*$I$10,0) -> 0 | J39: =IFERROR(J22*$I$11,0) -> 0 | K39: =IFERROR(K22*$I$12,0) -> 0 | L39: =IFERROR(L22*$I$13,0) -> 0 | M39: =IFERROR(M22*$I$14,0) -> 0 | N39: =IFERROR(N22*$I$15,0) -> 0 | O39: =IFERROR(O22*$I$16,0) -> 0
C40: Ethel | D40: =IFERROR(D23*$I$5,0) -> 0 | E40: =IFERROR(E23*$I$6,0) -> 0 | F40: =IFERROR(F23*$I$7,0) -> 0 | G40: =IFERROR(G23*$I$8,0) -> 0 | H40: =IFERROR(H23*$I$9,0) -> 0 | I40: =IFERROR(I23*$I$10,0) -> 0 | J40: =IFERROR(J23*$I$11,0) -> 0 | K40: =IFERROR(K23*$I$12,0) -> 0 | L40: =IFERROR(L23*$I$13,0) -> 0 | M40: =IFERROR(M23*$I$14,0) -> 0 | N40: =IFERROR(N23*$I$15,0) -> 0 | O40: =IFERROR(O23*$I$16,0) -> 0
C41: Mary | D41: =IFERROR(D24*$I$5,0) -> 0 | E41: =IFERROR(E24*$I$6,0) -> 0 | F41: =IFERROR(F24*$I$7,0) -> 0 | G41: =IFERROR(G24*$I$8,0) -> 0 | H41: =IFERROR(H24*$I$9,0) -> 0 | I41: =IFERROR(I24*$I$10,0) -> 0 | J41: =IFERROR(J24*$I$11,0) -> 0 | K41: =IFERROR(K24*$I$12,0) -> 0 | L41: =IFERROR(L24*$I$13,0) -> 0 | M41: =IFERROR(M24*$I$14,0) -> 0 | N41: =IFERROR(N24*$I$15,0) -> 0 | O41: =IFERROR(O24*$I$16,0) -> 0
C42: Isaac | D42: =IFERROR(D25*$I$5,0) -> 2000 | E42: =IFERROR(E25*$I$6,0) -> 2250 | F42: =IFERROR(F25*$I$7,0) -> 1500 | G42: =IFERROR(G25*$I$8,0) -> 2400 | H42: =IFERROR(H25*$I$9,0) -> 2080 | I42: =IFERROR(I25*$I$10,0) -> 0 | J42: =IFERROR(J25*$I$11,0) -> 2020 | K42: =IFERROR(K25*$I$12,0) -> 2002 | L42: =IFERROR(L25*$I$13,0) -> 0 | M42: =IFERROR(M25*$I$14,0) -> 0 | N42: =IFERROR(N25*$I$15,0) -> 0 | O42: =IFERROR(O25*$I$16,0) -> 0
C43: Ruth | D43: =IFERROR(D26*$I$5,0) -> 0 | E43: =IFERROR(E26*$I$6,0) -> 0 | F43: =IFERROR(F26*$I$7,0) -> 0 | G43: =IFERROR(G26*$I$8,0) -> 0 | H43: =IFERROR(H26*$I$9,0) -> 0 | I43: =IFERROR(I26*$I$10,0) -> 0 | J43: =IFERROR(J26*$I$11,0) -> 0 | K43: =IFERROR(K26*$I$12,0) -> 0 | L43: =IFERROR(L26*$I$13,0) -> 0 | M43: =IFERROR(M26*$I$14,0) -> 0 | N43: =IFERROR(N26*$I$15,0) -> 0 | O43: =IFERROR(O26*$I$16,0) -> 0
C44: Eric.N | D44: =IFERROR(D27*$I$5,0) -> 0 | E44: =IFERROR(E27*$I$6,0) -> 0 | F44: =IFERROR(F27*$I$7,0) -> 0 | G44: =IFERROR(G27*$I$8,0) -> 0 | H44: =IFERROR(H27*$I$9,0) -> 0 | I44: =IFERROR(I27*$I$10,0) -> 0 | J44: =IFERROR(J27*$I$11,0) -> 0 | K44: =IFERROR(K27*$I$12,0) -> 0 | L44: =IFERROR(L27*$I$13,0) -> 0 | M44: =IFERROR(M27*$I$14,0) -> 0 | N44: =IFERROR(N27*$I$15,0) -> 0 | O44: =IFERROR(O27*$I$16,0) -> 0
C45: Daniel | D45: =IFERROR(D28*$I$5,0) -> 0 | E45: =IFERROR(E28*$I$6,0) -> 0 | F45: =IFERROR(F28*$I$7,0) -> 0 | G45: =IFERROR(G28*$I$8,0) -> 0 | H45: =IFERROR(H28*$I$9,0) -> 0 | I45: =IFERROR(I28*$I$10,0) -> 0 | J45: =IFERROR(J28*$I$11,0) -> 0 | K45: =IFERROR(K28*$I$12,0) -> 0 | L45: =IFERROR(L28*$I$13,0) -> 0 | M45: =IFERROR(M28*$I$14,0) -> 0 | N45: =IFERROR(N28*$I$15,0) -> 0 | O45: =IFERROR(O28*$I$16,0) -> 0
...

Sheet TAKE HOME
C3: FINAL TAKE HOME
D4: Total savings | E4: Dividents | F4: Fees/penaltie | G4: Admni cost | H4: Take home
C5: Eric | D5: =SAVING!P22 -> 0 | E5: =SUM(INCOME!D39:O39) -> 0 | H5: =SUM(D5:F5)-G5 -> 0
C6: Ethel | D6: =SAVING!P23 -> 0 | E6: =SUM(INCOME!D40:O40) -> 0 | H6: =SUM(D6:F6)-G6 -> 0
C7: Mary | D7: =SAVING!P24 -> 0 | E7: =SUM(INCOME!D41:O41) -> 0 | H7: =SUM(D7:F7)-G7 -> 0
C8: Isaac | D8: =SAVING!P25 -> 89000 | E8: =SUM(INCOME!D42:O42) -> 14252 | H8: =SUM(D8:F8)-G8 -> 103252
C9: Ruth | D9: =SAVING!P26 -> 0 | E9: =SUM(INCOME!D43:O43) -> 0 | H9: =SUM(D9:F9)-G9 -> 0
C10: Eric.N | D10: =SAVING!P27 -> 0 | E10: =SUM(INCOME!D44:O44) -> 0 | H10: =SUM(D10:F10)-G10 -> 0
C11: Daniel | D11: =SAVING!P28 -> 0 | E11: =SUM(INCOME!D45:O45) -> 0 | H11: =SUM(D11:F11)-G11 -> 0
C12: Casmir | D12: =SAVING!P29 -> 0 | E12: =SUM(INCOME!D46:O46) -> 0 | H12: =SUM(D12:F12)-G12 -> 0
C13: Phanice | D13: =SAVING!P30 -> 0 | E13: =SUM(INCOME!D47:O47) -> 0 | H13: =SUM(D13:F13)-G13 -> 0
C14: Duncan | D14: =SAVING!P31 -> 0 | E14: =SUM(INCOME!D48:O48) -> 0 | H14: =SUM(D14:F14)-G14 -> 0
C15: Allan | D15: =SAVING!P32 -> 0 | E15: =SUM(INCOME!D49:O49) -> 0 | H15: =SUM(D15:F15)-G15 -> 0
C16: Colince | D16: =SAVING!P33 -> 0 | E16: =SUM(INCOME!D50:O50) -> 0 | H16: =SUM(D16:F16)-G16 -> 0
... C18: Ann | D18: =SAVING!P35 -> 0 | E18: =SUM(INCOME!D52:O52) -> 0 | H18: =SUM(D18:F18)-G18 -> 0

Sheet Budget
C2: INCOME SOURCE
D3: January | E3: February | F3: March | G3: April | H3: May | I3: June | J3: July | K3: August | L3: September | M3: October | N3: November | O3: December
C4: Salary | D4: 51000 | E4: 56000 | F4: 63000 | H4: 67000 | K4: 58000
C6: savings | D6: 20000 | E6: 10000 | F6: 13000 | H6: 7000 | K6: 2000
C8: loan | D8: 40000 | E8: 25000 | F8: 0 | H8: 60000 | K8: 50050
C11: repayment | D11: 0 | E11: 22000 | F11: 22550 | H11: 42500 | K11: 52520
C13: balance | D13: =D4-D6+D8-D11 -> 71000 | E13: =E4-E6+E8-E11 -> 49000 | F13: =F4-F6+F8-F11 -> 27450 | G13: =G4-G6+G8-G11 -> 0 | H13: =H4-H6+H8-H11 -> 77500 | I13: =I4-I6+I8-I11 -> 0 | J13: =J4-J6+J8-J11 -> 0 | K13: =K4-K6+K8-K11 -> 53530 | ... O13: =O4-O6+O8-O11 -> 0
C15: EXEPENDITURE
C17: Rent | D17: 7500 | E17: 7500 | F17: 7500 | H17: 7500 | K17: 7500 | L17: 7500
C18: Fees | D18: 22000 | E18: 20000 | F18: 22000 | H18: =SUM(R9:T9) -> 0 | L18: 24000
C19: Grocery | D19: 13000 | E19: 15000 | F19: 17000 | H19: 17000 | L19: 5850
C20: Transport | D20: 8000 | E20: 3000 | F20: 3000 | H20: 3500 | K20: 11250
C21: Black tax | D21: 5000 | E21: 7000 | F21: 7000 | K21: 5000
C22: Shoes | D22: 3000 | E22: 0 | F22: 0 | H22: 7000 | K22: 3000
C23: utilities | D23: 4000 | E23: 3000 | F23: 3000 | H23: 3000 | K23: 3000
C24: Bal+ve,-ve | D24: =D13-SUM(D17:D23) -> 8500 | E24: =E13-SUM(E17:E23) -> -6500 | F24: =F13-SUM(F17:F23) -> -32050 | G24: =G13-SUM(G17:G23) -> 0 | H24: =H13-SUM(H17:H23) -> 39500 | I24: =I13-SUM(I17:I23) -> 0 | J24: =J13-SUM(J17:J23) -> 0 | K24: =K13-SUM(K17:K23) -> 23780 | ... O24: =O13-SUM(O17:O23) -> 0
